Workbook

Sheet 指标汇总
A1: 官方扩充评测｜25题人工复核工作簿
A2: 用途：复核自动裁判标记的引用错误、准确度为0或存在幻觉的关键题。请勿覆盖自动结果，仅填写黄色输入区域。
A4: 冻结评测总题数 | B4: 100 | C4: 运行成功率 | D4: 1 | E4: 关键复核题 | F4: 25 | G4: 人工复核完成 | H4: =COUNTIF(人工复核!$U$4:$U$28,"已确认") -> 25
A6: 自动引用正确率 | B6: 0.8 | C6: 自动回答准确度 | D6: 0.695 | E6: 自动幻觉率 | F6: 0.08 | G6: 三项一致率 | H6: =IF(COUNTIF(人工复核!$U$4:$U$28,"已确认")=0,"",COUNTIF(人工复核!$V$4:$V$28,"一致")/COUNTIF(人工复核!$U$4:$U$28,"已确认")) -> 0.36
A8: 人工引用正确率 | B8: =SUM(人工复核!$O$4:$O$28)/COUNT(人工复核!$O$4:$O$28) -> 0.44 | C8: 人工回答准确度 | D8: =SUM(人工复核!$P$4:$P$28)/(2*COUNT(人工复核!$P$4:$P$28)) -> 0.36 | E8: 人工幻觉率 | F8: =SUM(人工复核!$Q$4:$Q$28)/COUNT(人工复核!$Q$4:$Q$28) -> 0.24 | G8: 已确认题数 | H8: =COUNTIF(人工复核!$U$4:$U$28,"已确认") -> 25
A9: 复核步骤
A10: 1. 在“人工复核”中对照标准答案、实际回答和“引用明细”中的证据。
A11: 2. 填写人工引用正确、人工回答准确度、人工幻觉三个黄色评分字段。
A12: 3. 选择根因分类，填写处理建议与复核备注，并将状态改为“已确认”或“需讨论”。
A13: 4. “一致性”由公式自动计算；先完成复核，再决定是否修改切片、提示词或标准答案。
A16: 颜色说明
A17: 黄色：人工输入 | C17: 红色：错误/幻觉 | E17: 橙色：部分正确 | G17: 绿色：正确/一致
A20: 批量评测来源：D:\Tools\CodeTools\Projects\medical-device-test-rag\evaluation\results\batch_eval_100_official_expansion_v1_frozen_merged_20260729_133356.json
A21: 自动裁判来源：D:\Tools\CodeTools\Projects\medical-device-test-rag\evaluation\results\judge_eval_100_20260729_151729.json

Sheet 人工复核
A1: 关键问题人工复核记录（25题）
A2: 黄色列由人工填写；自动评分与冻结回答保持只读。引用全文请按问题ID到“引用明细”查看。
A3: 问题ID | B3: 预期文档 | C3: 预期定位 | D3: 评测问题 | E3: 标准答案要点 | F3: 实际回答 | G3: 实际Top1文档 | H3: 严格Top1 | I3: 严格Top3 | J3: 引用概览 | K3: 自动引用正确 | L3: 自动回答准确度 | M3: 自动幻觉 | N3: 自动评分理由 | O3: 人工引用正确 | P3: 人工回答准确度 | Q3: 人工幻觉 | R3: 根因分类 | S3: 处理建议 | T3: 复核备注 | U3: 复核状态 | V3: 三项一致性
A4: E001 | B4: DOC006 | C4: 一、适用范围 | D4: 《医疗器械可用性工程注册审查指导原则》适用于哪些医疗器械，明确不适用于哪类产品？ | E4: 适用于第二类、第三类医疗器械可用性工程的注册申报，不适用于体外诊断试剂；注册申请人可参照其要求开展全部医疗器械的可用性工程工作。 | F4: 当前知识库中未检索到足够依据，无法给出确定结论。 | G4: DOC010 | H4: 0 | I4: 0 | J4: 1. DOC010｜0.3828｜50 See FDA’s Guidance “Applying Human Factors and Usability Engineering to Medical Devices.” 2. DOC009｜0.3216｜.39 ContainsNonbindingRecommendations Content of Premarket Submissions for Device Software Functions Guidance for Industry and Food and Drug Administr… 3. DOC010｜0.2947｜26 See the Medical Device and Health IT Joint Security Plan version 2 (JSP2). 4. DOC011｜0.2867｜.18 Appendix B: Examples. ContainsNonbindingRecommendations Off-The-Shelf Software Use in MedicalDevices Guidance for Industry and Food and Drug Admin… 5. DOC010｜0.2865｜32 Details on the content for security risk management plans and reports beyond those specifically identified can be found in AAMI TIR57 Principles fo… 6. DOC009｜0.2805｜ContainsNonbindingRecommendations It is the sponsor's responsibility to proactively and comprehensively consider risks as part of the device's risk as… 7. DOC011｜0.2791｜ContainsNonbindingRecommendations Off-The-Shelf Software Use in Medical Devices Guidance for Industry and Food and Drug Administration Staff Document … 8. DOC013｜0.2784｜1. GB 9706.1 医用电气设备 第1部分：基本安全和基本性能的通用要求 2. GB/T 16886.1 医疗器械生物学评价 第1部分：风险管理过程中的评价与试验 3. GB/T 19000-2016 质量管理体系 基础和术语 4. GB/T 20002.4-2015 标准中特定内容的起草 第… | K4: 0 | L4: 0 | M4: 0 | N4: 待评测回答为拒绝回答，未引用任何证据，未提供任何有效信息，与人工标准答案明显矛盾。 | O4: 0 | P4: 0 | Q4: 0 | R4: 检索未命中 | S4: 为DOC006适用范围条款补充标题、关键词和同义问法，降低英文跨文档片段干扰。 | T4: Top 8未出现DOC006；回答谨慎拒答，未增加具体无依据事实。 | U4: 已确认 | V4: =IF(U4<>"已确认","待复核",IF(AND(K4=O4,L4=P4,M4=Q4),"一致","不一致")) -> 一致
A5: E003 | B5: DOC006 | C5: 二、主要概念（三）医疗器械使用情况和用户操作情形 | D5: 正常使用、非正常使用、正确使用和错误使用之间是什么关系？ | E5: 使用情况分为正常使用和非正常使用；正常使用是按说明书及常识惯例操作，非正常使用则相反。正常使用按结果又分正确使用和错误使用；错误使用是用户行动或行动缺失导致器械响应异于预期，可能降低安全有效性并需要风险控制。 | F5: 【结论】 当前知识库中未检索到足够依据，无法给出确定结论。 【依据】 知识库中未出现“正常使用”“正确使用”“错误使用”的定义或其相互关系的描述。仅对“非正常使用”（reasonably foreseeable misuse）给出了定义：[ID:5] 中定义“Reasonably foreseeable misuse – use of a product or system in a way not intended by the manufacturer, but which can result from readily predictable human behavior.”（可合理预见的误用——以制造商未预期的方式使用产品或系统，但可由容易预测的人为行为导致）。 【适用说明】 省略。 | G5: DOC010 | H5: 0 | I5: 0 | J5: 1. DOC010｜0.2918｜74 For more information about current review practices for 510(k) submission, see FDA’s guidance “The 510(k) Program: Evaluating Substantial Equivalen… 2. DOC009｜0.2766｜ContainsNonbindingRecommendations should provide a high-level diagram that communicates the overview and points to the other diagrams that provide add… 3. DOC009｜0.2672｜15. An implantable cardiac pacemaker used to treat bradycardia Description: The device is an implanted, programmable dual-chamber pulse generator inte… 4. DOC009｜0.2669｜20. An infusion pump intended for use in a health care facility to pump fluids and medications into a patient. Description: The device is intended for… 5. DOC010｜0.2667｜75 For the purposes of this control, “information” includes the software/firmware itself, as well as input and output data. ## Source page 43 When cho… 6. DOC010｜0.2639｜99 Definition is adapted from Medical Device and Health IT Joint Security Plan version 2 (JSP2). ## Source page 60 Denial of Service – prevention or i… 7. DOC009｜0.2562｜17. A multi-parameter patient monitor for use in a professional healthcare facility. Description: The device is a multi-parameter monitor intended for… 8. DOC009｜0.2536｜3. A non-invasive blood pressure monitor with inflatable cuff. Description: The device is intended to measure a person's systolic and diastolic blood … | K5: 1 | L5: 0 | M5: 0 | N5: 待评测回答的主要结论为'无法给出确定结论'，该结论基于引用的证据（仅包含非正常使用定义）得出，证据支持此结论，因此citation_correct=1。但回答未能覆盖人工标准答案要求的术语关系，核心结论（无法确定）与标准答案明确给出的关系相矛盾，且没有提供任何与问题直接相关的有效关系内容，因此answer_accuracy=0。回答未增加无依据的具体事实，hallucination=0。 | O5: 0 | P5: 0 | Q5: 1 | R5: 检索未命中 | S5: 补充DOC006中正常使用、异常使用、正确使用与使用错误的结构化关系切片；提示词仅可表述“本轮未检索到”。 | T5: 未回答四类关系，且错误断言知识库未包含相关定义，属于对知识库范围的无依据判断。 | U5: 已确认 | V5: =IF(U5<>"已确认","待复核",IF(AND(K5=O5,L5=P5,M5=Q5),"一致","不一致")) -> 不一致
A6: E004 | B6: DOC006 | C6: 三、基本原则（二）使用风险导向 | D6: 医疗器械使用风险分为哪三级，分别如何判定？ | E6: 按伤害严重度分为高、中、低三级：错误使用可能导致严重伤害或死亡为高风险，可能导致轻微伤害为中风险，不可能导致伤害为低风险。高使用风险器械含关键任务，中、低使用风险器械不含关键任务，且应在采取风险控制措施前判定。 | F6: 【结论】 当前知识库中未检索到足够依据，无法给出确定结论。 【依据】 检索片段涉及FDA医疗器械软件上市前提交指南、网络安全和OTS软件相关文档，但均未提供“使用风险三级分类”及其判定方法的具体要求或定义。 | G6: DOC009 | H6: 0 | I6: 0 | J6: 1. DOC009｜0.4512｜ContainsNonbindingRecommendations It is the sponsor's responsibility to proactively and comprehensively consider risks as part of the device's risk as… 2. DOC010｜0.3311｜2. Security Architecture Views In addition to the design and development requirements,46 Subclause 8.5 of ISO 13485 requires that manufacturers establ… 3. DOC010｜0.3298｜46 See Subclause 7.3 of ISO 13485. ## Source page 27 FDA recommends providing, at minimum, the following types of views in premarket submissions: · Gl… 4. DOC009｜0.3284｜(1) Risk Management Plan FDA recommends sponsors submit a risk management plan to support the effectiveness of the risk management activities and proc… 5. DOC011｜0.3260｜(2)Implementation The speed required by the medical device system dictates the hardware selection, the network interface cards and transmissions proto… 6. DOC010｜0.3229｜34 The MDIC/MITRE Playbook for Threat Modeling Medical Devices is an educational resource that discusses the threat modeling process, different threat… 7. DOC011｜0.3225｜6. How will you keep track of (controll4) the OTS Software? An appropriate plan should answer the following questions: · What measures have been desig… 8. DOC010｜0.3184｜42 NIST 800-160 vol. 1 rev. 1, Engineering Trustworthy Secure Systems states that security architecture definition process generates a set of represen… | K6: 0 | L6: 0 | M6: 0 | N6: 待评测回答声称未检索到足够依据，但实际引用证据为空，无法支持该结论；且回答明确拒绝回答，未提供任何有效信息，与人工标准答案明显矛盾。 | O6: 0 | P6: 0 | Q6: 0 | R6: 检索未命中 | S6: 为DOC006三档使用风险分级建立独立完整切片并添加自然语言相关问题。 | T6: Top 8未出现DOC006，回答拒答；未虚构具体分级。 | U6: 已确认 | V6: =IF(U6<>"已确认","待复核",IF(AND(K6=O6,L6=P6,M6=Q6),"一致","不一致")) -> 一致
A7: E007 | B7: DOC006 | C7: 六、技术考量（一）临床试验 | D7: 临床试验能否替代用户界面确认测试，为什么？ | E7: 通常不能替代，只能作为支持和补充，因为某些关键任务测试可能危及受试者，且临床试验参与人数未必满足总结性可用性测试要求。仅在特殊情况下，临床试验满足总结性可用性测试要求时才可作为用户界面确认测试。 | F7: 【结论】 当前知识库中未检索到足够依据，无法给出确定结论。 | G7: DOC011 | H7: 0 | I7: 0 | J7: 1. DOC011｜0.2872｜(6)Product Configuration The submission must identify the product to be considered. Therefore, the product configuration provided should specify: · Ha… 2. DOC011｜0.2793｜ContainsNonbindingRecommendations OTs Software labeling should indicate the minimum hardware platforms on which the software is validated to run (e.g.… 3. DOC009｜0.2776｜..24 ...25 H. Software Testing as part of Verification and Validation.... 4. DOC009｜0.2695｜(2) Risk Assessment A risk assessment that includes a risk analysis, risk evaluation, risk control and a benefit-risk analysis (where applicable) shou… 5. DOC009｜0.2694｜(3)Risk Management Report A risk management report should be provided to: · Show how the risk management plan has been appropriately implemented. Demo… 6. DOC009｜0.2637｜9. An in vitro nucleic acid test for the qualitative detection of Human Papillomavirus (HPV) DNA in human cervical specimens. Description: The test is… 7. DOC009｜0.2522｜23. A continuous glucose monitoring system. Description: The device is intended to provide real time, continuous glucose monitoring for the management… 8. DOC009｜0.2466｜20. An infusion pump intended for use in a health care facility to pump fluids and medications into a patient. Description: The device is intended for… | K7: 0 | L7: 0 | M7: 0 | N7: 待评测回答未引用任何证据，直接拒绝回答，人工标准答案明确存在，因此主要结论无证据支持且准确度为0。 | O7: 0 | P7: 0 | Q7: 0 | R7: 检索未命中 | S7: 强化DOC006关于临床试验不能常规替代用户界面确认的条款标题与相关问题。 | T7: 未召回目标条款，回答未提供有效结论。 | U7: 已确认 | V7: =IF(U7<>"已确认","待复核",IF(AND(K7=O7,L7=P7,M7=Q7),"一致","不一致")) -> 一致
A8: E008 | B8: DOC006 | C8: 六、技术考量（二）进口医疗器械 | D8: 进口医疗器械为什么原则上需要在中国开展用户界面确认工作？ | E8: 因为中外用户、使用场景及可用性工程申报要求可能存在差异，原有用户界面设计未必能保证在中国安全有效使用。原则上应按使用风险级别在中国开展确认，除非有详实材料证明中外差异对确认无显著影响。 | F8: 【结论】 当前知识库中未检索到足够依据，无法给出确定结论。 【依据】 知识库中仅包含 FDA 和 OTS 医疗器械软件相关文档，未涉及进口医疗器械在中国开展用户界面确认工作的具体要求。 | G8: DOC010 | H8: 0 | I8: 0 | J8: 1. DOC010｜0.3745｜21 For more information on reasonably foreseeable misuse, see the IMDRF final guidance “Principles and Practices for Medical Device Cybersecurity.” ##… 2. DOC010｜0.3605｜# DOC010 FDA Cybersecurity in Medical Devices (2026) - Part 7 > Source pages 49-56 of the official PDF. Page-preserving RAGFlow ingestion part. ## Sou… 3. DOC011｜0.3233｜ContainsNonbindingRecommendations OTs Software labeling should indicate the minimum hardware platforms on which the software is validated to run (e.g.… 4. DOC011｜0.3228｜(6)Product Configuration The submission must identify the product to be considered. Therefore, the product configuration provided should specify: · Ha… 5. DOC010｜0.3111｜74 For more information about current review practices for 510(k) submission, see FDA’s guidance “The 510(k) Program: Evaluating Substantial Equivalen… 6. DOC010｜0.3021｜49 Users often manage security risks in medical device systems by an end user or within a larger risk management framework like the NIST CSF. ## Sourc… 7. DOC010｜0.2952｜46 See Subclause 7.3 of ISO 13485. ## Source page 27 FDA recommends providing, at minimum, the following types of views in premarket submissions: · Gl… 8. DOC010｜0.2848｜3. Interoperability Considerations Interoperability is an important consideration when assessing the cybersecurity of the end-to-end medical device sy… | K8: 0 | L8: 0 | M8: 1 | N8: 待评测回答的主要结论（无法给出确定结论）没有实际引用证据支持，实际引用证据缺失；回答完全回避问题，未提供任何正确有效信息，与人工标准答案核心要点矛盾；回答断言知识库内容的具体事实缺乏证据支持，构成幻觉。 | O8: 0 | P8: 0 | Q8: 1 | R8: 检索未命中 | S8: 为进口器械中国用户界面确认要求增加结构化切片；约束模型不得把本轮检索结果等同于知识库全部内容。 | T8: 未命中DOC006，并错误声称知识库只有FDA/OTS资料。 | U8: 已确认 | V8: =IF(U8<>"已确认","待复核",IF(AND(K8=O8,L8=P8,M8=Q8),"一致","不一致")) -> 一致
A9: E015 | B9: DOC007 | C9: 五、技术考量（二）电池 | D9: 移动医疗器械的电池管理应考虑哪些安全有效性问题？ | E9: 应考虑电池容量、续航时间、充放电、剩余电量和低电量提示、电池故障或断电处理等要求，并结合核心功能和使用场景控制电量不足或异常供电导致的风险。 | F9: 【结论】 当前知识库中未检索到足够依据，无法给出确定结论。 【依据】 无。知识库中的文档（如FDA网络安全指南、OTS软件指南等）均未涉及移动医疗器械的电池管理相关内容。 | G9: DOC010 | H9: 0 | I9: 0 | J9: 1. DOC010｜0.4237｜42 NIST 800-160 vol. 1 rev. 1, Engineering Trustworthy Secure Systems states that security architecture definition process generates a set of represen… 2. DOC010｜0.4229｜49 Users often manage security risks in medical device systems by an end user or within a larger risk management framework like the NIST CSF. ## Sourc… 3. DOC011｜0.4229｜ContainsNonbindingRecommendations OTs Software labeling should indicate the minimum hardware platforms on which the software is validated to run (e.g.… 4. DOC010｜0.4218｜21 For more information on reasonably foreseeable misuse, see the IMDRF final guidance “Principles and Practices for Medical Device Cybersecurity.” ##… 5. DOC010｜0.4050｜16 In the postmarket context, design and development may also be important to ensure medical device cybersecurity and maintain medical device safety a… 6. DOC011｜0.3955｜.18 Appendix B: Examples. ContainsNonbindingRecommendations Off-The-Shelf Software Use in MedicalDevices Guidance for Industry and Food and Drug Admin… 7. DOC011｜0.3949｜(1) Requirements Analysis B. Speed - The response time required for safe and effective operation determines the LAN data rate (bandwidth) for the medi… 8. DOC010｜0.3928｜23 For more information regarding the substantial equivalence review standard, please refer to FDA’s guidance, “The 510(k) Program: Evaluating Substan… | K9: 0 | L9: 0 | M9: 0 | N9: 待评测回答声称未检索到足够依据、无法给出结论，但人工标准答案明确列出了应考虑的要点，回答实际未引用任何有效证据支持其结论，且未提供任何与问题相关的正确有效信息，因此准确性为0。 | O9: 0 | P9: 0 | Q9: 1 | R9: 检索未命中 | S9: 为DOC007电池管理要求增加完整切片、关键词和常见问法；统一安全拒答措辞。 | T9: 未命中DOC007，并错误断言知识库文档不覆盖电池管理。 | U9: 已确认 | V9: =IF(U9<>"已确认","待复核",IF(AND(K9=O9,L9=P9,M9=Q9),"一致","不一致")) -> 不一致
A10: E029 | B10: DOC009 | C10: VI.B Software Description | D10: FDA上市前申报中的软件描述应至少说明哪些内容？ | E10: 应概述重要软件特征和功能，必要时用图像、流程图和状态图说明；还应说明软件在器械预期用途中的作用、预期用户和患者、主要输入输出、分析方式及硬件平台。修改器械应标明既往申报并突出影响安全有效性的变化。 | F10: 【结论】 FDA上市前申报中的软件描述应至少包含软件需求规格说明（SRS）和系统与软件架构图。 【依据】 根据《Content of Premarket Submissions for Device Software Functions》第VI节的建议： - 软件需求规格说明（SRS）应记录软件的需求，通常规定输入和输出、软件将执行的功能、硬件、性能、接口、用户交互、错误定义和处理、预期操作环境、源自风险评估的安全相关要求以及软件将接受的所有范围、限制、默认值和特定值 [ID:4]。 - 系统与软件架构图的目的是呈现设备设计的路线图，以清晰展示构成系统和软件的模块和层次、模块和层次之间的关系、数据输入/输出及数据流，以及用户或外部产品如何与系统和软件交互 [ID:4]。 此外，若设备使用OTS软件，根据《Off-The-Shelf Software Use in Medical Devices》第III.A节的建议： - 对于基本和增强文档级别，应提供OTS软件功能和特性的概述和描述 [ID:1]。 【适用说明】 本回答基于FDA的上市前申报建议。针对使用OTS软件的设备，需额外提供OTS软件的描述，但不同文档级别下的详细程度可能不同。 | G10: DOC009 | H10: 1 | I10: 1 | J10: 1. DOC009｜0.5843｜.39 ContainsNonbindingRecommendations Content of Premarket Submissions for Device Software Functions Guidance for Industry and Food and Drug Administr… 2. DOC011｜0.5814｜.18 Appendix B: Examples. ContainsNonbindingRecommendations Off-The-Shelf Software Use in MedicalDevices Guidance for Industry and Food and Drug Admin… 3. DOC011｜0.5244｜5. How do you know it works? · Based on documentation Level (i.e., Basic or Enhanced) determined for the device software as discussed in the guidance … 4. DOC011｜0.5219｜6. How will you keep track of (controll4) the OTS Software? An appropriate plan should answer the following questions: · What measures have been desig… 5. DOC009｜0.5134｜(3)Risk Management Report A risk management report should be provided to: · Show how the risk management plan has been appropriately implemented. Demo… 6. DOC011｜0.4968｜(3) Software Testing as Part of Verification and Validation As in the establishment of a product baseline, verification and validation (V&V) activitie… 7. DOC010｜0.4949｜7.3.7). Design and development validation includes validation of device software. In addition, Subclause 7.1 of ISO 13485 specifies that the “organiza… 8. DOC011｜0.4888｜(1)Safety Introduction of new or modified OTS software component(s) to a product baseline may impact the safety of the product. Therefore, a safety im… | K10: 0 | L10: 1 | M10: 1 | N10: 主要结论要求包含系统与软件架构图，但实际引用证据中未出现相关内容，因此主要结论未得到完全支持（citation_correct=0）。回答在依据中提到了SRS应包含输入输出、硬件等正确内容，部分覆盖标准答案要点，但遗漏了软件作用、预期用户、分析方式等核心要求，故准确度为1。回答增加了无依据的系统与软件架构图要求，构成幻觉。 | O10: 0 | P10: 0 | Q10: 1 | R10: 检索未命中 | S10: 将DOC009 VI.B Software Description与SRS、架构图相邻章节拆分并加清晰标题，优先召回精确章节。 | T10: 把SRS和架构图误当成Software Description的内容，核心结论答非所问且概念混合。 | U10: 已确认 | V10: =IF(U10<>"已确认","待复核",IF(AND(K10=O10,L10=P10,M10=Q10),"一致","不一致")) -> 不一致
A11: E033 | B11: DOC009 | C11: VI.D Software Requirements Specification | D11: FDA建议软件需求规范（SRS）覆盖哪些需求，并具备哪些质量特性？ | E11: SRS通常覆盖输入输出、功能、硬件、性能、接口、用户交互、错误定义与处理、运行环境、安全相关要求，以及允许的范围、限值、默认值和具体值。每项需求应可追溯，并评价准确性、完整性、一致性、可测试性、正确性和清晰性。 | F11: 【结论】 FDA建议软件需求规格（SRS）应覆盖输入/输出、功能、硬件、性能、接口、用户交互、错误定义与处理、预期操作环境、从风险评估推导的安全相关需求，以及软件接受的所有范围、极限、默认值和具体值。SRS的每个需求应可追溯，并应对其准确性、完整性、一致性、可测试性、正确性和清晰度进行评估。 【依据】 依据《DOC009_FDA_premarket_device_software_functions_2023.pdf》中关于“Software Requirements Specification (SRS)”的描述： - SRS通常应指定“inputs and outputs, functions that the software will perform, hardware, performance, interfaces, user interaction, error definition and handling, intended operating environment, safety related requirements derived from a risk assessment (Refer to Section VI.C Risk Management File) and all ranges, limits, defaults, and specific values that the software will accept”。[ID:0] - SRS中的每个需求应可追溯，且FDA建议SRS应被评估其“accuracy, completeness, consistency, testability, correctness, and clarity”。[ID:0] 【适用说明】 该建议适用于向FDA提交的医疗器械软件上市前申请，包括510(k)、De Novo、PMA等类型，且适用于所有文档级别（Basic或Enhanced）。[ID:1] | G11: DOC009 | H11: 1 | I11: 1 | J11: 1. DOC009｜0.5016｜(3)Risk Management Report A risk management report should be provided to: · Show how the risk management plan has been appropriately implemented. Demo… 2. DOC009｜0.4127｜.39 ContainsNonbindingRecommendations Content of Premarket Submissions for Device Software Functions Guidance for Industry and Food and Drug Administr… 3. DOC010｜0.3820｜# DOC010 FDA Cybersecurity in Medical Devices (2026) - Part 2 > Source pages 9-16 of the official PDF. Page-preserving RAGFlow ingestion part. ## Sour… 4. DOC010｜0.3777｜46 See Subclause 7.3 of ISO 13485. ## Source page 27 FDA recommends providing, at minimum, the following types of views in premarket submissions: · Gl… 5. DOC009｜0.3667｜..15 Software Requirements Specification (SRS) 6. DOC011｜0.3274｜ContainsNonbindingRecommendations OTs Software labeling should indicate the minimum hardware platforms on which the software is validated to run (e.g.… 7. DOC011｜0.3224｜.18 Appendix B: Examples. ContainsNonbindingRecommendations Off-The-Shelf Software Use in MedicalDevices Guidance for Industry and Food and Drug Admin… 8. DOC011｜0.3192｜2. What are the Computer System Specifications for the OTS Software? For what configuration will the OTS software be validated? The following should b… | K11: 1 | L11: 2 | M11: 1 | N11: 主要结论（SRS覆盖的需求和质量特性）有引用证据直接支持；回答完整覆盖了人工标准答案的所有核心要点，故准确度为2；但适用说明部分增加了引用证据中未出现的具体申请类型和文档级别，构成幻觉。 | O11: 1 | P11: 2 | Q11: 0 | R11: 自动裁判误判 | S11: 无需修改知识库；校准裁判，使其综合检查全部引用片段及适用范围证据。 | T11: SRS内容、质量属性和适用范围均有DOC009引用支持，回答完整。 | U11: 已确认 | V11: =IF(U11<>"已确认","待复核",IF(AND(K11=O11,L11=P11,M11=Q11),"一致","不一致")) -> 不一致
A12: E034 | B12: DOC009 | C12: VI.E System and Software Architecture Diagram | D12: 系统与软件架构图应帮助FDA理解哪些关系？ | E12: 应展示构成系统和软件的模块与层次、模块和层次间关系、数据输入输出及流向，以及用户和外部产品（含IT基础设施及外设）如何与系统和软件交互。 | F12: 【结论】 系统与软件架构图应帮助FDA理解以下四类关系： 1. 构成系统与软件的模块及层次； 2. 模块及层次之间的相互关系； 3. 数据输入/输出及模块与层次间的数据流； 4. 用户或外部产品（包括IT基础设施和外围设备，如无线连接的医疗器械）与系统及软件的交互方式。 【依据】 依据DOC009_FDA_premarket_device_software_functions_2023.pdf中第VI.E节“系统与软件架构图”（System and Software Architecture Diagram）的原文说明，该图的目的是展示设备设计的路线图，以帮助清晰理解上述四方面内容[ID:2]。 | G12: DOC009 | H12: 1 | I12: 1 | J12: 1. DOC009｜0.5511｜ContainsNonbindingRecommendations should provide a high-level diagram that communicates the overview and points to the other diagrams that provide add… 2. DOC009｜0.5100｜27. A drug-device combination, with the device constituent part detecting ingestion of the drug component to prevent treatment failure. Description: T… 3. DOC009｜0.4860｜(3)Risk Management Report A risk management report should be provided to: · Show how the risk management plan has been appropriately implemented. Demo… 4. DOC010｜0.4637｜# DOC010 FDA Cybersecurity in Medical Devices (2026) - Part 7 > Source pages 49-56 of the official PDF. Page-preserving RAGFlow ingestion part. ## Sou… 5. DOC009｜0.4478｜..20 System and Software Architecture Diagram... Software Design Specification (SDS). F. Basic Documentation Level.... 6. DOC009｜0.4472｜..28 Appendix B: System and Software Architecture Diagram Examples 7. DOC010｜0.4061｜46 See Subclause 7.3 of ISO 13485. ## Source page 27 FDA recommends providing, at minimum, the following types of views in premarket submissions: · Gl… 8. DOC011｜0.4030｜(2)Implementation The speed required by the medical device system dictates the hardware selection, the network interface cards and transmissions proto… | K12: 0 | L12: 2 | M12: 0 | N12: 待评测回答的结论正确且完整覆盖人工标准答案要点，但实际引用的证据内容与架构图无关，无法支持主要结论，故citation_correct为0。回答未增加无依据事实，hallucination为0。 | O12: 1 | P12: 2 | Q12: 0 | R12: 自动裁判误判 | S12: 无需修改知识库；裁判应识别引用编号对应的完整DOC009片段，而非只看片段开头。 | T12: 四类架构关系与DOC009 VI.E原文一致，引用充分。 | U12: 已确认 | V12: =IF(U12<>"已确认","待复核",IF(AND(K12=O12,L12=P12,M12=Q12),"一致","不一致")) -> 不一致
A13: E035 | B13: DOC009 | C13: VI.F Software Design Specification | D13: Basic和Enhanced文档等级对软件设计规范（SDS）的提交要求有何不同？ | E13: Basic等级通常不要求在上市前申报中提交SDS，但应在器械设计历史文件中内部保存，FDA必要时可要求补充；Enhanced等级应提交一个或一组SDS，说明软件如何实现SRS、模块和接口的详细设计以及对SRS的可追溯性。 | F13: 【结论】 Basic Documentation Level下，FDA不推荐在注册申报资料中提交SDS，企业应将设计信息记录在DHF中，FDA可能在审查中要求补充；Enhanced Documentation Level下，企业需要提交一份或多份SDS文档，详细说明技术设计、如何完整正确实现SRS要求以及与SRS的追溯性。 【依据】 - DOC009_FDA_premarket_device_software_functions_2023.pdf（Table 1和Section VI.F）指出： - Basic Documentation Level：“FDA is not recommending the SDS as part of the premarket submission. Sponsor should document this information on the design via the DHF for the device. During premarket review, FDA may request additional information, if needed, to evaluate the safety and effectiveness of the device.” - Enhanced Documentation Level：“SDS documentation, including sufficient information that would allow FDA to understand the technical design details of how the software functions, how the software design completely and correctly implements all the requirements of the SRS, and how the software design traces to the SRS in terms of intended use, functionality, safety, and effectiveness.” [ID:1]（Table 1部分） - 同一文档Section VI.F进一步说明Enhanced Level下的SDS要求：“A singular SDS document or set of SDS documents that provide the technical design details of how the software functions, how the software design completely and correctly implements all the requirements of the SRS and how the software design traces to the SRS in terms of intended use, functionality, safety, and effectiveness.” [ID:4] 【适用说明】 以上要求适用于器械软件功能的注册申报（Premarket Submission）场景，需根据器械的文档等级（Basic或Enhanced）区别对待。 | G13: DOC011 | H13: 0 | I13: 1 | J13: 1. DOC011｜0.4362｜6. How will you keep track of (controll4) the OTS Software? An appropriate plan should answer the following questions: · What measures have been desig… 2. DOC009｜0.4147｜ContainsNonbindingRecommendations It is the sponsor's responsibility to proactively and comprehensively consider risks as part of the device's risk as… 3. DOC011｜0.3766｜5. How do you know it works? · Based on documentation Level (i.e., Basic or Enhanced) determined for the device software as discussed in the guidance … 4. DOC009｜0.3669｜..20 System and Software Architecture Diagram... Software Design Specification (SDS). F. Basic Documentation Level.... 5. DOC009｜0.3540｜ContainsNonbindingRecommendations should provide a high-level diagram that communicates the overview and points to the other diagrams that provide add… 6. DOC011｜0.3482｜(1) A traumatic brain injury (TBl) eye movement assessment aid Description: The device is a prescription device that is intended to track a patient's … 7. DOC009｜0.3469｜14. An electric breast pump. Description: The device is intended to be used by lactating women to express and collect milk from their breasts. The dev… 8. DOC009｜0.3355｜.39 ContainsNonbindingRecommendations Content of Premarket Submissions for Device Software Functions Guidance for Industry and Food and Drug Administr… | K13: 0 | L13: 2 | M13: 0 | N13: 主要结论在内容上正确且完整覆盖标准答案要点，但实际引用的证据片段（[ID:1]和[ID:4]）并未直接包含待评测回答所引用的具体文字，无法支持其主要结论，因此citation_correct为0。回答本身没有增加无依据的具体事实，hallucination为0。 | O13: 0 | P13: 2 | Q13: 0 | R13: 检索未命中 | S13: 为DOC009 VI.F Basic/Enhanced SDS要求建立自包含切片并添加级别对比问法。 | T13: 回答与标准答案一致，但返回证据未直接包含Basic与Enhanced的完整判定要求。 | U13: 已确认 | V13: =IF(U13<>"已确认","待复核",IF(AND(K13=O13,L13=P13,M13=Q13),"一致","不一致")) -> 一致
A14: E037 | B14: DOC009 | C14: VI.I Software Version History | D14: FDA建议软件版本历史以什么方式记录，最终条目还需说明什么？ | E14: 应从受设计控制的版本开始，以逐项表格记录测试日期、版本号及相对前一测试版本的变更。最后一项应为拟发布版本，并说明测试版本与发布版本的差异及其对安全有效性的潜在影响。 | F14: 当前知识库中未检索到足够依据，无法给出确定结论。 | G14: DOC011 | H14: 0 | I14: 1 | J14: 1. DOC011｜0.3663｜1. What is it? For each component of OTS software used, the following should be specified: Title and Manufacturer of the OTS software. Version Level, … 2. DOC009｜0.3662｜...26 Software Version History.... I. 3. DOC011｜0.3614｜6. How will you keep track of (controll4) the OTS Software? An appropriate plan should answer the following questions: · What measures have been desig… 4. DOC010｜0.3557｜# DOC010 FDA Cybersecurity in Medical Devices (2026) - Part 7 > Source pages 49-56 of the official PDF. Page-preserving RAGFlow ingestion part. ## Sou… 5. DOC010｜0.3481｜2. Changes Unlikely to Impact Cybersecurity In general, changes unlikely to impact cybersecurity could include changes in materials, sterilization met… 6. DOC010｜0.3480｜46 See Subclause 7.3 of ISO 13485. ## Source page 27 FDA recommends providing, at minimum, the following types of views in premarket submissions: · Gl… 7. DOC010｜0.3403｜7.3.10 (Design and Development Files) and Subclause 4.2.3 (Medical Device File) of ISO 13485. To assist FDA’s assessment of the device risks and assoc… 8. DOC009｜0.3354｜(3)Risk Management Report A risk management report should be provided to: · Show how the risk management plan has been appropriately implemented. Demo… | K14: 0 | L14: 0 | M14: 0 | N14: 回答未引用任何证据，主要结论“无法给出确定结论”没有证据支持，且与标准答案要求的具体记录方式相矛盾，未提供任何有效信息。 | O14: 0 | P14: 0 | Q14: 0 | R14: 检索未命中 | S14: 将DOC009 VI.I版本历史要求整理为独立完整切片并补充相关问题。 | T14: 仅召回目录或相邻章节，回答拒答。 | U14: 已确认 | V14: =IF(U14<>"已确认","待复核",IF(AND(K14=O14,L14=P14,M14=Q14),"一致","不一致")) -> 一致
A15: E043 | B15: DOC010 | C15: V.A.2 Cybersecurity Risk Assessment | D15: 网络安全风险评估为何不能只按历史概率量化，FDA建议重点评估什么？ | E15: 网络攻击可能有意或无意发生，威胁会变化，难以用历史数据可靠预测事件概率。评估应重点分析漏洞的可利用性及其在器械和所在系统中的风险，可采用最坏情况假设或对合理可利用性评估给出论证。 | F15: 【结论】 网络安全风险评估不能仅按历史概率量化，因为安全风险管理的根本方法并非概率性方法，而是重点评估漏洞的可利用性（exploitability）。FDA建议制造商根据设备和运行系统所构成的风险水平来评估已识别的风险。 【依据】 根据《FDA Cybersecurity in Medical Devices (2026) - Part 3》（Source page 18）的说明：安全风险管理所采用的非概率性方法并非ISO 14971下安全风险管理的基本方法 [ID:7]；安全风险评估过程重点关注可利用性，即利用设备和/或系统中存在的漏洞的能力。FDA建议制造商根据设备和运行系统所构成的风险水平来评估已识别的风险。 【适用说明】 该建议适用于医疗器械上市前网络安全风险管理活动。 | G15: DOC010 | H15: 1 | I15: 1 | J15: 1. DOC010｜0.4884｜34 The MDIC/MITRE Playbook for Threat Modeling Medical Devices is an educational resource that discusses the threat modeling process, different threat… 2. DOC010｜0.3981｜27 ANSI/ISA-62443-4-1 Security for industrial automation and control systems Part 4-1: Product security development life-cycle requirements outlines a… 3. DOC010｜0.3969｜46 See Subclause 7.3 of ISO 13485. ## Source page 27 FDA recommends providing, at minimum, the following types of views in premarket submissions: · Gl… 4. DOC010｜0.3797｜30 See 21 CFR Part 820. ## Source page 16 risk assessment and be assessed for additional control measures or risk transfer31 to the user/operator, or,… 5. DOC009｜0.3743｜(1) Risk Management Plan FDA recommends sponsors submit a risk management plan to support the effectiveness of the risk management activities and proc… 6. DOC010｜0.3730｜47 For any testing tools or software used, the details provided may include, but may not be limited to, the name of the tool, version information as a… 7. DOC010｜0.3721｜2. Cybersecurity Risk Assessment As a part of security risk management, security risks and controls should be assessed for residual risks as part of a… 8. DOC010｜0.3706｜# DOC010 FDA Cybersecurity in Medical Devices (2026) - Part 3 > Source pages 17-24 of the official PDF. Page-preserving RAGFlow ingestion part. ## Sou… | K15: 0 | L15: 1 | M15: 1 | N15: 待评测回答的主要结论（不能仅按历史概率量化，重点评估可利用性）在实际引用的证据中未得到直接支持；回答包含部分正确内容（重点评估可利用性），但遗漏了标准答案中关于攻击有意无意、威胁变化及最坏情况假设等核心要点，且增加了引用证据中不存在的具体事实（非概率性方法表述）。 | O15: 1 | P15: 1 | Q15: 0 | R15: 回答遗漏 | S15: 在回答提示词中为网络安全风险评估加入“难以预测、可利用性、最坏情形/合理说明”核对清单。 | T15: 引用直接支持可利用性评估；回答遗漏故障可有意/无意发生及最坏情形或合理说明。 | U15: 已确认 | V15: =IF(U15<>"已确认","待复核",IF(AND(K15=O15,L15=P15,M15=Q15),"一致","不一致")) -> 不一致
... A28: E095 | B28: DOC016 | C28: 第二章 第十二条 | D28: 评价缺陷医疗器械时应重点考虑哪些因素？ | E28: 应考虑是否符合强制标准和产品技术要求、使用中是否发生故障或伤害、现有环境下是否会造成伤害及相关证据、涉及地区和人群、伤害程度、发生概率、短期和长期后果及其他可能伤害因素。 | F28: 当前知识库中未检索到足够依据，无法给出确定结论。 | G28: DOC010 | H28: 0 | I28: 0 | J28: 1. DOC010｜0.3886｜19 See Subclause 7.3 of ISO 13485. ## Source page 11 the device when connectivity-based features are added after marketing and distribution, or when v… 2. DOC011｜0.3832｜ContainsNonbindingRecommendations OTs Software labeling should indicate the minimum hardware platforms on which the software is validated to run (e.g.… 3. DOC010｜0.3565｜81 For the purposes of this guidance, “allow-list” means a list of discrete entities, such as hosts or applications that are known to be benign and ar… 4. DOC009｜0.3503｜(1) Risk Management Plan FDA recommends sponsors submit a risk management plan to support the effectiveness of the risk management activities and proc… 5. DOC009｜0.3418｜.39 ContainsNonbindingRecommendations Content of Premarket Submissions for Device Software Functions Guidance for Industry and Food and Drug Administr… 6. DOC010｜0.3407｜# DOC010 FDA Cybersecurity in Medical Devices (2026) - Part 7 > Source pages 49-56 of the official PDF. Page-preserving RAGFlow ingestion part. ## Sou… 7. DOC011｜0.3362｜6. How will you keep track of (controll4) the OTS Software? An appropriate plan should answer the following questions: · What measures have been desig… 8. DOC011｜0.3342｜(1)Safety Introduction of new or modified OTS software component(s) to a product baseline may impact the safety of the product. Therefore, a safety im… | K28: 0 | L28: 0 | M28: 0 | N28: 回答未能提供任何有效信息，拒绝作答，且无引用证据支持主要结论，核心事实完全缺失。 | O28: 0 | P28: 0 | Q28: 0 | R28: 检索未命中 | S28: 为DOC016缺陷器械评价因素建立完整列表型切片并添加相关问题。 | T28: 未召回DOC016，回答安全拒答且未增加无依据事实。 | U28: 已确认 | V28: =IF(U28<>"已确认","待复核",IF(AND(K28=O28,L28=P28,M28=Q28),"一致","不一致")) -> 一致

Sheet 引用明细
A1: 关键问题引用片段明细
A2: 每条记录对应一次RAGFlow引用；按问题ID或引用排名筛选。
A3: 问题ID | B3: 引用排名 | C3: 文档代码 | D3: 文档名称 | E3: 相似度 | F3: Chunk ID | G3: 引用内容 | H3: 位置信息
A4: E001 | B4: 1 | C4: DOC010 | D4: DOC010_FDA_cybersecurity_2026_part04_pages025-032.md | E4: 0.38280945 | F4: a3fc239d5babe08a | G4: 50 See FDA’s Guidance “Applying Human Factors and Usability Engineering to Medical Devices.” | H4: [[10, 9, 9, 9, 9]]
A5: E001 | B5: 2 | C5: DOC009 | D5: DOC009_FDA_premarket_device_software_functions_2023.pdf | E5: 0.32155232 | F5: 9e18fbb8a6c29413 | G5: .39 ContainsNonbindingRecommendations Content of Premarket Submissions for Device Software Functions Guidance for Industry and Food and Drug Administration Staff This guidance represents the current thinking of the Food and Drug Administration (FDA or Agency) on this topic. It does not establish any rights for any person and is not binding on FDA or the public. You can use an alternative approach if it satisfies the requirements of the applicable statutes and regulations. To discuss an alternative approach, contact the FDA staff or Office responsible for this guidance as listed on the title page. I. Introduction This guidance document is intended to provide information regarding the recommended documentation for premarket submissions for FDA's evaluation of the safety and effectiveness of device software functions, which are software functions that meet the definition of a device under section 201(h) of the Federal Food, Drug, and Cosmetic Act (FD&C Act).1 This document replaces FDA's Guidance for the Content of Premarket Submissions for Software Contained in Medical Devices issued on May 11, 2005, and updates FDA's thinking related to the documentation FDA recommends sponsors include for the review of device software functions in premarket submissions. The recommendations in this guidance are intended to facilitate FDA's premarket review. This guidance describes information that would be typically generated and documented? during software development, verification, and validation. The least burdensome approach was applied to identify the minimum amount of information that, based on our experience, would generally be needed to support a premarket submission for a device that uses software. During premarket review, FDA may request additional information that is needed to evaluate the submission. For example, in order to demonstrate a reasonable assurance of safety and effectiveness for devices ContainsNonbindingRecommendations that use software, documentation related to the requirements of the Quality System Regulation (QSR) (21 CFR Part 820) is often a necessary part of the premarket submission. As part of QSR design controls, a manufacturer must “establish and maintain procedures for validating the device design,” which “shall include software validation and risk analysis, where appropriate' (21 CFR 820.30(g)) The documentation recommended in this guidance is based on FDA's experience evaluating the safety and effectiveness of device software. However, sponsors may use alternative approaches and provide different documentation so long as their approach and documentation satisfy premarket submission requirements in applicable statutory provisions and regulations. For the current edition(s) of the FDA-recognized consensus standard(s) referenced in this document, see the FDA Recognized Consensus Standards Database.? For more information regarding use of consensus standards in regulatory submissions, please refer to the FDA guidance titled Appropriate Use of Voluntary Consensus Standards in Premarket Submissions for Medical Devices4 and Standards Development and the Use of Standards in Regulatory Submissions Reviewed in the Center for Biologics Evaluation and Research.5 As stated above, this guidance identifies the software information FDA considers to generally be necessary to support a premarket submission. The recommendations in this guidance are also intended to facilitate FDA's premarket review. FDA anticipates that the Agency and industry will need up to 60 days after the publication of this guidance to operationalize the recommendations discussed. However, CDRH intends to review any such information if submitted at any time. In general, FDA's guidance documents do not establish legally enforceable responsibilities. Instead, guidances describe the Agency's current thinking on a topic and should be viewed only as recommendations, unless specific regulatory or statutory requirements are cited. The use of the word should in Agency guidances means that something is suggested or recommended, but not required. ll.Background The purpose of this guidance is to describe FDA's thinking on the recommended documentation sponsors should include in premarket submissions for FDA's evaluation of the safety and effectiveness of device software functions. This thinking recognizes recent changes to the FD&C Act made by the 21st Century Cures Act (Cures Act), which amended section 520 of the FD&C Act and excludes certain software functions from the device definition. It also considers the rapidly evolving nature of digital health and recent FDA-recognized consensus standards related to software. This guidance, as described in Section II (Scope), is intended to complement other existing guidance documents that provide recommendations related to software, including the ContainsNonbindingRecommendations guidance documents listed below. The following guidance documents represent a subset of FDA guidances with digital health content° relevant to premarket software documentation activities. Please note the list is not exhaustive and is subject to change: Multiple Function Device Products: Policy and Considerations Off-The-Shelf Software Use in Medical Devices8 Design Considerations and Premarket Submission Recommendations for Interoperable MedicalDevices9 General Principles of Software Validation10 Content of Premarket Submissions for Management of Cybersecurity in Medical Devices* Cybersecurity for Networked Medical Devices Containing Off-The-Shelf (OTS) Software12 Applying Human Factors and Usability Engineering to Medical Devices 13 FDA encourages the consideration of these guidances when developing device software functions and preparing premarket software documentation. The emergence of consensus standards related to software has helped to improve the consistency and quality of software development and documentation, particularly with respect to activities such as risk assessment and management. When possible, FDA harmonized the terminology and recommendations in this guidance with software-related consensus standards, such as the following examples. The following standards are not intended to represent an exhaustive list and are subject to change:14 · ANSI/AAMI/ISO 14971: Medical devices - Applications of risk management to medical devices ·ANSI/AAMI/IEC 62304: Medical Device Software - Software Life Cycle Processes ANSIAAMI SW91: Classification of defects in health software ContainsNonbindingRecommendations The Agency encourages the consideration of these FDA-recognized consensus standards when developing device software functions and preparing premarket software documentation. When assessing the appropriate Documentation Level for the device and the overall recommended documentation for inclusion in a premarket submission, please refer to Section V (Documentation Level) and Section VI (Recommended Documentation) of this guidance. Section 3308 of the Food and Drug Omnibus Reform Act of 2022, Title II of Division FF of the Consolidated Appropriations Act, 2023, Pub. L. No. 117-328 ("FDORA"), enacted on December 29, 2022, added section 515C “Predetermined Change Control Plans for Devices" to the FD&C Act (section 515C). Under section 515C, FDA can approve or clear a predetermined change control plan (PCCP) for a device that describes planned changes that may be made to the device and that would otherwise require a supplemental premarket approval application or premarket notification. For example, section 515C provides that a supplemental premarket approval application (section 515C(a)) or a premarket notification (section 515C(b)) is not required for a change to a device if the change is consistent with a PCCP that is approved or cleared by FDA. Section 515C also provides that FDA may require that a PCCP include labeling for safe and effective use of a device as such device changes pursuant to such plan, notification requirements if the device does not function as intended pursuant to such plan, and performance requirements for changes made under the plan. If you are interested in proposing a PCCP in your marketing submission, we encourage you to submit a Pre-Submission to engage in further discussion with CDRH. See FDA's guidance “Requests for Feedback and Meetings for Medical Device Submissions: The Q-Submission Program? available at https://www.fda.gov/regulatory- information/search-fda-guidance-documents/requests-feedback-and-meetings-medical-device- submissions-q-submission-program. Iml.Scope For the purposes of this document, FDA refers to a software function that meets the definition of a device as a device software function. For any given product, the term “function" is a distinct purpose of the product, which could be the intended use or a subset of the intended use of the product.15 For example, a product with an intended use to analyze data has one function: analysis. A product with an intended use to store, transfer, and analyze data has three functions: (1) storage, (2) transfer, and (3) analysis. As this example illustrates, a product may contain multiple functions. This guidance is intended to cover device software functions. Examples include, but are not limited to, firmware and other means for software-based control of medical devices, software accessories to medical devices, and software onlyl° function(s) that meet the definition of a device. ContainsNonbindingRecommendations This guidance recommends the information to provide in a premarket submission that includes a device software function(s). For the purposes of this guidance, the term premarket submission includes, but is not limited to, premarket notification (510(k)) submission, De Novo classification request, Premarket Approval (PMA) application, Investigational Device Exemption (IDE), Humanitarian Device Exemption (HDE), or Biologics License Application (BLA). Certain devices are subject to premarket review through a BLA under section 351 of the Public Health Service Act. This guidance does not apply to automated manufacturing and Quality System softwarel7 or software that is not a device. For further information or to clarify the documentation expectations, please contact the responsible FDA review division. Generally, the recommendations in this guidance apply to the device constituent part of a combination product18 (such as drug-device and biologic-device combination products) when the device constituent part19 includes a device software function, including combination products assigned to CDER and CBER regulated under drug or biological product market submission types. For more information, contact the FDA review Division that will have the lead review for the combination product.20 Other FDA guidance documents may recommend additional software-related documentation for inclusion in a premarket submission. For example, recommendations regarding cybersecurity information to include in a device premarket submission can be found in the guidances “Content of Premarket Submissions for Management of Cybersecurity in Medical Devices"” and "Cybersecurity for Networked Medical Devices Containing Off-The-Shelf (OTS) Software.*21 Section If (Background) references other relevant guidance documents that supplement the recommendations contained in this guidance. ContainsNonbindingRecommendations Device software functions subject to specific special controls22 may require additional software- related documentation in a premarket submission. As applicable, please refer to the relevant special controls for the device. This guidance does not apply to the software-related documentation that may be needed to evaluate postmarket software device issues, including corrections and removals.23 While this guidance identifies the documentation sponsors should include in premarket submissions, this guidance is not meant to provide recommendations regarding how device software should be developed, verified, and validated. This guidance does not recommend the use of any specific software life cycle model or development methodology (such as waterfall model or other variations thereof, spiral model, Agile model, etc.). Sponsors should establish a software life cycle model that is appropriate for their product and organization, and meets the applicable regulatory requirements. The software life cycle model that is selected should cover the software throughout its total product life cycle. Regardless of the software lifecycle model being utilized, sponsors should ensure that the establishment of their design history file (DHF)24 documentation is synchronized with their software development, verification, and validation efforts. DHF documentation that is created retrospectively or following a prolonged period of time after actual software development, verification, and validation efforts could raise concerns regarding whether a developer has adequate control of their design process. For recommendations on device software development, verification, and validation, please consult software-related FDA-recognized voluntary consensus standards and other software-related FDA guidance documents referenced in this guidance (e.g., “General Principles of Software Validation'25). IV. Definitions The following terms are used for the purposes of this guidance: Device Software Function - Software function that meets the device definition in section 201(h) of the FD&C Act. As discussed above, the term “function" is a distinct purpose of the product, which could be the intended use or a subset of the intended use of the product ContainsNonbindingRecommendations Off-the-Shelf (OTS) Software26 - A generally available software component used by a device manufacturer for which the manufacturer cannot claim complete software life cycle control (e.g., operating system, printer/display libraries). Serious Injury27 - An injury or illness that: Is life threatening, 1) Results in permanent impairment of a body function or permanent damage to a 2) body structure, or Necessitates medical or surgical intervention to preclude permanent impairment 3) of a body function or permanent damage to a body structure. Permanent is defined as irreversible impairment or damage to a body structure or function, excluding trivial impairment or damage. Software Verification and Software Validation - This guidance uses the terms “software verification' and “software validation," which are described in further detail below. · For the purposes of this guidance, software verification is confirmation by objective evidence that the output of a particular phase of development meets all the input requirements for that phase. Software verification involves evaluating the consistency, completeness, and correctness of the software and its supporting documentation, as it is being developed, and provides support for a subsequent conclusion that software is validated. Software testing is one of several verification activities intended to confirm that the software development output meets its input requirements. Other verification activities include source code evaluations (e.g., code inspections and walkthroughs), document inspections, design reviews, technical evaluations (e.g., software architecture, software detailed design, etc.) and traceability analyses (e.g., software requirements specification to software design specification (and vice versa), source code to software design specification (and vice versa), and test cases to source code and to software design specification). For example, the input and output of the design phase are known as Software Requirements Specification (SRS) and Software Design Specification (SDS), respectively. In this case, software verification would involve confirming by objective evidence (e.g., reviews, traceability analysis) that the software design as documented in the SDS (i.e., output) correctly and completely implements all the requirements of the SRS (i.e., input) · For the purposes of this guidance, software validation refers to establishing, by objective evidence, that the software specifications conform to user needs and intended uses, and that the particular requirements implemented through software can be consistently fulfilled. Software validation is a part of design validation of the finished device. It involves checking for proper operation of the software in its actual or simulated use environment, including integration into the final device where appropriate. Software validation is highly dependent upon comprehensive software testing and other ContainsNonbindingRecommendations verification tasks previously completed at each stage of the software development life cycle. Planning, requirements, traceability, testing, risk assessment, design reviews, change management, and many other aspects of good software engineering are important activities that together help to support a conclusion that software is validated. The above descriptions of software verification and software validation are consistent with FDA's thinking as described in the guidance “General Principles of Software Validation." V. Documentation Level The recommended documentation for a premarket submission depends on the device's risk to a patient, a user of a device, or others in the environment of use. FDA intends to take a risk-based approach to help determine the device's Documentation Level, which is either Basic or Enhanced. The purpose of the Documentation Level is to help identify the minimum amount of information that would support a premarket submission that includes device software functions. The Documentation Level of a device is based on the risks of its device software function(s) in the context of the device's intended use,"° such that the documentation level reflects the device as a whole. For the purpose of this guidance: Enhanced Documentation should be provided for any premarket submission that includes device software function(s) where a failure or flaw of any device software function(s) could present a hazardous situation with a probable29 risk of death or serious injury,3° either to a patient, user of the device, or others in the environment of use. These risks should be assessed prior to implementation of risk control measures. Sponsors should consider the risks in the context of the device's intended use (e.g., impacts to safety, treatment, and/or diagnosis), and other relevant considerations. Basic Documentation should be provided for any premarket submission that includes device software function(s) where Enhanced Documentation does not apply. When determining the Documentation Level, sponsors should consider all known or foreseeable software hazards and hazardous situations associated with the device, including those resulting from reasonably foreseeable misuse, whether intentional or unintentional, prior to the implementation of risk control measures. This also includes the likelihood that device functionality is intentionally or unintentionally compromised by inadequate device cybersecurity. | H5: [[4, 522, 539, 584, 594], [5, 206, 405, 37, 51], [5, 77, 535, 82, 136], [5, 88, 525, 161, 217], [5, 68, 536, 241, 310], [5, 69, 206, 338, 354], [5, 70, 541, 378, 489], [5, 69, 533, 502, 599], [6, 206, 405, 38, 49], [6, 70, 533, 80, 147], [6, 70, 536, 161, 299], [6, 69, 538, 313, 394], [6, 70, 510, 411, 425], [6, 69, 532, 423, 478], [6, 72, 201, 502, 516], [6, 70, 537, 539, 650], [7, 206, 405, 38, 50], [7, 70, 536, 77, 107], [7, 70, 368, 104, 120], [7, 106, 525, 135, 280], [7, 70, 494, 292, 319], [7, 68, 538, 333, 421], [7, 88, 533, 430, 486], [8, 206, 405, 38, 50], [8, 70, 527, 79, 147], [8, 70, 539, 162, 288], [8, 70, 533, 285, 409], [8, 71, 154, 429, 447], [8, 69, 538, 470, 566], [8, 70, 520, 581, 633], [9, 206, 405, 38, 50], [9, 70, 540, 80, 148], [9, 71, 527, 148, 175], [9, 69, 515, 188, 232], [9, 69, 538, 245, 331], [9, 69, 535, 339, 436], [10, 206, 405, 38, 49], [10, 69, 533, 77, 121], [10, 69, 506, 134, 165], [10, 69, 538, 174, 410], [10, 70, 193, 430, 447], [10, 72, 375, 471, 485], [10, 71, 538, 499, 538], [11, 206, 405, 38, 49], [11, 69, 538, 79, 121], [11, 71, 282, 133, 147], [11, 139, 232, 146, 160], [11, 108, 119, 149, 160], [11, 140, 523, 161, 175], [11, 107, 119, 162, 175], [11, 141, 529, 175, 203], [11, 107, 118, 190, 202], [11, 142, 540, 203, 243], [11, 72, 509, 260, 283], [11, 88, 538, 301, 547], [11, 89, 533, 565, 659], [12, 206, 405, 39, 50], [12, 106, 537, 79, 135], [12, 70, 508, 148, 176], [12, 70, 274, 197, 213], [12, 69, 534, 234, 306], [12, 70, 527, 320, 359], [12, 71, 230, 374, 388], [12, 106, 533, 401, 497], [12, 106, 523, 511, 539], [12, 72, 538, 553, 622]]
A6: E001 | B6: 3 | C6: DOC010 | D6: DOC010_FDA_cybersecurity_2026_part02_pages009-016.md | E6: 0.29472886 | F6: 930585027e9cb1d8 | G6: 26 See the Medical Device and Health IT Joint Security Plan version 2 (JSP2). | H6: [[17, 16, 16, 16, 16]]
